<robot name = "2DPlannar">

<!-- Kinematic Properties (Joints) -->
	<joint name="world_joint" type="fixed">
		<parent link="world"/>
		<child link="base_link"/>
		<origin rpy="0 0 0" xyz="0 0 0"/>
	</joint>
	<joint name="joint1" type="continuous">
		<parent link="base_link"/>
		<child link="link1"/>
		<origin rpy="0 0 0" xyz="0 0 0"/>
		<axis xyz="0 0 1"/>
	</joint>
	<joint name="joint2" type="continuous">
		<parent link="link1"/>
		<child link="link2"/>
		<origin rpy="0 0 0" xyz="0.0254 0 0"/>
		<axis xyz="0 0 1"/>
	</joint>
	
<!-- Inertial Properties (Links) -->
	<link name="world"/>
	<link name="base_link">
		<inertial>
			<mass value="0"/>
			<origin rpy="0 0 0" xyz="0 0 0"/>
			<inertia ixx="0" ixy="0" ixz="0" iyy="0" iyz="0" izz="0"/>
		</inertial>
	</link>
	
	<link name="link1">
		<inertial>
			<mass value="5"/>
			<origin rpy="0 0 0" xyz="0 0 0"/>
			<inertia ixx="1" ixy="0" ixz="0" iyy="1" iyz="0" izz="1"/>
		</inertial>
		<visual>
			<origin rpy="0 0 0" xyz="0 0 0" />
			<geometry>
				<capsule radius="0.02" length="0.0254"/>
			</geometry>
		</visual>
		<collision>
			<origin rpy="0 0 0" xyz="0 0 0" />
			<geometry>
				<capsule radius="0.02" length="0.0254"/>
			</geometry>
		</collision>
	</link>
	
	<link name="link2">
		<inertial>
			<mass value="5"/>
			<origin rpy="0 0 0" xyz="0.0254 0 0"/>
			<inertia ixx="1" ixy="0" ixz="0" iyy="1" iyz="0" izz="1"/>
		</inertial>
		<visual>
			<origin rpy="0 0 0" xyz="0.02540 0"/>
			<geometry>
				<capsule radius="0.02" length="0.0254"/>
			</geometry>
		</visual>
		<collision>
			<origin rpy="0 0 0" xyz="0.0254 0 0"/>
			<geometry>
				<capsule radius="0.02" length="0.0254"/>
			</geometry>
		</collision>
	</link>
</robot>